<?xml version="1.0" encoding="utf-8"?>
<!-- This URDF was automatically created by SolidWorks to URDF Exporter! Originally created by Stephen Brawner (brawner@gmail.com) 
     Commit Version: 1.6.0-4-g7f85cfe  Build Version: 1.6.7995.38578
     For more information, please see http://wiki.ros.org/sw_urdf_exporter -->
<robot
  name="robot_base" xmlns:xacro="http://www.ros.org/wiki/xacro">
  <xacro:property name="radius" value="0.055" />
  <xacro:property name="length" value="0.05" />
  <xacro:property name="wheel_orientation" value="1 0 0" />
  <xacro:property name="collision_transform" value="0 1.57079632679 1.57079632679" />
  
  <link
    name="base_link">
    <inertial>
      <origin
        xyz="-0.00910410219928872 -9.31202386654388E-05 -0.00269627899619879"
        rpy="0 0 0" />
      <mass
        value="2.54161575728203" />
      <inertia
        ixx="0.00900908568706438"
        ixy="-1.49036665189052E-06"
        ixz="0.000180180089420441"
        iyy="0.0120513643006957"
        iyz="-7.98162115966032E-07"
        izz="0.0202435224080604" />
    </inertial>
    <visual>
      <origin
        xyz="0 0 0"
        rpy="0 0 0" />
      <geometry>
        <mesh
          filename="package://mirte_description/meshes/base_link.STL" />
      </geometry>
      <material
        name="">
        <color
          rgba="0.529411764705882 0.549019607843137 0.549019607843137 1" />
      </material>
    </visual>
    <collision>
      <origin
        xyz="0 0 0"
        rpy="0 0 0" />
      <geometry>
        <mesh
          filename="package://mirte_description/meshes/base_link.STL" />
      </geometry>
    </collision>
  </link>

  <!-- <link name="base_footprint"/>

  <joint name="base_joint" type="fixed">
      <parent link="base_footprint"/>
      <child link="base_link"/>
      <origin xyz="0 0 0.010" rpy="0 0 0"/>
  </joint>   -->

  <link
    name="front_left_wheel_link">
    <inertial>
      <origin
        xyz="-1.12107378935633E-10 6.41072041116797E-05 2.92491780795601E-10"
        rpy="0 0 0" />
      <mass
        value="0.266614983225976" />
      <inertia
        ixx="8.05457942774812E-05"
        ixy="-1.2260463258983E-14"
        ixz="1.9673439489928E-15"
        iyy="9.31956038960015E-05"
        iyz="-9.68884941818333E-15"
        izz="8.05457942705124E-05" />
    </inertial>
    <visual>
      <origin
        xyz="0 0 0"
        rpy="0 0 0" />
      <geometry>
        <mesh
          filename="package://mirte_description/meshes/front_left_wheel_link.STL" />
      </geometry>
      <material
        name="">
        <color
          rgba="0.792156862745098 0.819607843137255 0.933333333333333 1" />
      </material>
    </visual>
    <collision>
      <origin
        xyz="0 0 0"
        rpy="${collision_transform}" />
      <geometry>
        <cylinder radius="${radius}" length="${length}" />        
        <!-- <mesh
          filename="package://mirte_description/meshes/front_left_wheel_link.STL" /> -->
      </geometry>
    </collision>
  </link>
  <joint
    name="front_left_wheel_joint"
    type="continuous">
    <origin
      xyz="0.085 0.128 -0.0454999999999998"
      rpy="0 0 0" />
    <parent
      link="base_link" />
    <child
      link="front_left_wheel_link" />
    <axis
      xyz="0 1 0" />
  </joint>
  <link
    name="front_right_wheel_link">
    <inertial>
      <origin
        xyz="-1.9000166717742E-10 6.41072041136226E-05 2.1252127835325E-10"
        rpy="0 0 0" />
      <mass
        value="0.266614983226051" />
      <inertia
        ixx="8.05457942757E-05"
        ixy="-7.69167351689639E-14"
        ixz="-4.58661949809919E-15"
        iyy="9.31956038947893E-05"
        iyz="-9.60111009267714E-15"
        izz="8.05457942710754E-05" />
    </inertial>
    <visual>
      <origin
        xyz="0 0 0"
        rpy="0 0 0" />
      <geometry>
        <mesh
          filename="package://mirte_description/meshes/front_right_wheel_link.STL" />
      </geometry>
      <material
        name="">
        <color
          rgba="0.792156862745098 0.819607843137255 0.933333333333333 1" />
      </material>
    </visual>
    <collision>
      <origin
        xyz="0 0 0"
        rpy="${collision_transform}" />
      <geometry>
        <cylinder radius="${radius}" length="${length}" /> 
        <!-- <mesh
          filename="package://mirte_description/meshes/front_right_wheel_link.STL" /> -->
      </geometry>
    </collision>
  </link>
  <joint
    name="front_right_wheel_joint"
    type="continuous">
    <origin
      xyz="0.085 -0.128 -0.0454999999999999"
      rpy="0 0 0" />
    <parent
      link="base_link" />
    <child
      link="front_right_wheel_link" />
    <axis
      xyz="0 1 0" />
  </joint>
  <link
    name="rear_left_wheel_link">
    <inertial>
      <origin
        xyz="-1.90001639421844E-10 6.41072041137336E-05 2.12521299169932E-10"
        rpy="0 0 0" />
      <mass
        value="0.266614983226051" />
      <inertia
        ixx="8.05457942756755E-05"
        ixy="-7.6904280182912E-14"
        ixz="-4.57395497910921E-15"
        iyy="9.31956038947575E-05"
        iyz="-9.59312938568377E-15"
        izz="8.05457942710471E-05" />
    </inertial>
    <visual>
      <origin
        xyz="0 0 0"
        rpy="0 0 0" />
      <geometry>
        <mesh
          filename="package://mirte_description/meshes/rear_left_wheel_link.STL" />
      </geometry>
      <material
        name="">
        <color
          rgba="0.792156862745098 0.819607843137255 0.933333333333333 1" />
      </material>
    </visual>
    <collision>
      <origin
        xyz="0 0 0"
        rpy="${collision_transform}" />
      <geometry>
        <cylinder radius="${radius}" length="${length}" /> 
        <!-- <mesh
          filename="package://mirte_description/meshes/rear_left_wheel_link.STL" /> -->
      </geometry>
    </collision>
  </link>
  <joint
    name="rear_left_wheel_joint"
    type="continuous">
    <origin
      xyz="-0.0849999999999993 0.128 -0.045500000000002"
      rpy="0 0 0" />
    <parent
      link="base_link" />
    <child
      link="rear_left_wheel_link" />
    <axis
      xyz="0 1 0" />
  </joint>
  <link
    name="rear_right_wheel_link">
    <inertial>
      <origin
        xyz="-1.00091421262327E-10 6.41072041089319E-05 2.94731128391845E-10"
        rpy="0 0 0" />
      <mass
        value="0.26661498322592" />
      <inertia
        ixx="8.05457942778204E-05"
        ixy="-1.26520007959427E-14"
        ixz="4.82090522465438E-17"
        iyy="9.3195603896201E-05"
        iyz="-1.75713132076445E-14"
        izz="8.05457942703286E-05" />
    </inertial>
    <visual>
      <origin
        xyz="0 0 0"
        rpy="0 0 0" />
      <geometry>
        <mesh
          filename="package://mirte_description/meshes/rear_right_wheel_link.STL" />
      </geometry>
      <material
        name="">
        <color
          rgba="0.792156862745098 0.819607843137255 0.933333333333333 1" />
      </material>
    </visual>
    <collision>
      <origin
        xyz="0 0 0"
        rpy="${collision_transform}" />
      <geometry>
        <cylinder radius="${radius}" length="${length}" /> 
        <!-- <mesh
          filename="package://mirte_description/meshes/rear_right_wheel_link.STL" /> -->
      </geometry>
    </collision>
  </link>
  <joint
    name="rear_right_wheel_joint"
    type="continuous">
    <origin
      xyz="-0.0850000000000007 -0.128 -0.0454999999999994"
      rpy="0 0 0" />
    <parent
      link="base_link" />
    <child
      link="rear_right_wheel_link" />
    <axis
      xyz="0 1 0" />
  </joint>
  <link
    name="camera_link">
    <inertial>
      <origin
        xyz="-0.0222605569788096 0.00132191548038024 -0.00039200722199239"
        rpy="0 0 0" />
      <mass
        value="0.188133920336356" />
      <inertia
        ixx="0.00040830401695793"
        ixy="1.91366259472818E-05"
        ixz="-4.27256160719641E-06"
        iyy="6.91459456639027E-05"
        iyz="2.54332844338714E-06"
        izz="0.000449074814854817" />
    </inertial>
    <visual>
      <origin
        xyz="0 0 0"
        rpy="0 0 0" />
      <geometry>
        <mesh
          filename="package://mirte_description/meshes/camera_link.STL" />
      </geometry>
      <material
        name="">
        <color
          rgba="0.250980392156863 0.250980392156863 0.250980392156863 1" />
      </material>
    </visual>
    <collision>
      <origin
        xyz="0 0 0"
        rpy="0 0 0" />
      <geometry>
        <mesh
          filename="package://mirte_description/meshes/camera_link.STL" />
      </geometry>
    </collision>
  </link>
  <joint
    name="camera_joint"
    type="fixed">
    <origin
      xyz="0.146658788505756 0 0.0426999999999987"
      rpy="0 0 0" />
    <parent
      link="base_link" />
    <child
      link="camera_link" />
    <axis
      xyz="0 0 0" />
  </joint>
  <link
    name="lidar_link">
    <inertial>
      <origin
        xyz="-3.97749846947626E-10 -9.543860877243E-05 -0.0118651639742243"
        rpy="0 0 0" />
      <mass
        value="0.100511981883415" />
      <inertia
        ixx="3.39518063996325E-05"
        ixy="-2.92284267049194E-13"
        ixz="1.62111209504698E-12"
        iyy="3.44778101670497E-05"
        iyz="-1.1815579647801E-07"
        izz="4.1935853096105E-05" />
    </inertial>
    <visual>
      <origin
        xyz="0 0 0"
        rpy="0 0 0" />
      <geometry>
        <mesh
          filename="package://mirte_description/meshes/lidar_link.STL" />
      </geometry>
      <material
        name="">
        <color
          rgba="0.501960784313725 0.501960784313725 0.501960784313725 1" />
      </material>
    </visual>
    <collision>
      <origin
        xyz="0 0 0"
        rpy="0 0 0" />
      <geometry>
        <mesh
          filename="package://mirte_description/meshes/lidar_link.STL" />
      </geometry>
    </collision>
  </link>
  <joint
    name="lidar_joint"
    type="fixed">
    <origin
      xyz="0.1005 0 0.0072113248654052"
      rpy="0 0 0" />
    <parent
      link="base_link" />
    <child
      link="lidar_link" />
    <axis
      xyz="0 0 0" />
  </joint>
  <link
    name="front_right_ultrasound_link">
    <inertial>
      <origin
        xyz="4.30733527063271E-05 0.00367564883489799 6.9913657863175E-05"
        rpy="0 0 0" />
      <mass
        value="0.00383513951999244" />
      <inertia
        ixx="1.59365628586767E-07"
        ixy="8.54250314742398E-10"
        ixz="-3.40905422018182E-09"
        iyy="7.6875152346034E-07"
        iyz="-2.65062440645524E-09"
        izz="7.26221149125632E-07" />
    </inertial>
    <visual>
      <origin
        xyz="0 0 0"
        rpy="0 0 0" />
      <geometry>
        <mesh
          filename="package://mirte_description/meshes/front_right_ultrasound_link.STL" />
      </geometry>
      <material
        name="">
        <color
          rgba="0.792156862745098 0.819607843137255 0.933333333333333 1" />
      </material>
    </visual>
    <collision>
      <origin
        xyz="0 0 0"
        rpy="0 0 0" />
      <geometry>
        <mesh
          filename="package://mirte_description/meshes/front_right_ultrasound_link.STL" />
      </geometry>
    </collision>
  </link>
  <joint
    name="front_right_ultrasound_joint"
    type="fixed">
    <origin
      xyz="0.120282421780502 -0.05297775289576 -0.031"
      rpy="0 0 -1.86750229963393" />
    <parent
      link="base_link" />
    <child
      link="front_right_ultrasound_link" />
    <axis
      xyz="0 0 0" />
  </joint>
  <link
    name="front_left_ultrasound_link">
    <inertial>
      <origin
        xyz="-4.30733527062924E-05 -0.00367564883489804 6.99136578631437E-05"
        rpy="0 0 0" />
      <mass
        value="0.00383513951999246" />
      <inertia
        ixx="1.59365628586768E-07"
        ixy="8.54250314742599E-10"
        ixz="3.40905422018193E-09"
        iyy="7.68751523460337E-07"
        iyz="2.65062440645509E-09"
        izz="7.26221149125628E-07" />
    </inertial>
    <visual>
      <origin
        xyz="0 0 0"
        rpy="0 0 0" />
      <geometry>
        <mesh
          filename="package://mirte_description/meshes/front_left_ultrasound_link.STL" />
      </geometry>
      <material
        name="">
        <color
          rgba="0.792156862745098 0.819607843137255 0.933333333333333 1" />
      </material>
    </visual>
    <collision>
      <origin
        xyz="0 0 0"
        rpy="0 0 0" />
      <geometry>
        <mesh
          filename="package://mirte_description/meshes/front_left_ultrasound_link.STL" />
      </geometry>
    </collision>
  </link>
  <joint
    name="front_left_ultrasound_joint"
    type="fixed">
    <origin
      xyz="0.120282421780502 0.05297775289576 -0.031"
      rpy="0 0 1.86750229963393" />
    <parent
      link="base_link" />
    <child
      link="front_left_ultrasound_link" />
    <axis
      xyz="0 0 0" />
  </joint>
  <link
    name="rear_left_ultrasound_link">
    <inertial>
      <origin
        xyz="4.30733527062785E-05 0.00367564883489802 6.99136578631784E-05"
        rpy="0 0 0" />
      <mass
        value="0.00383513951999244" />
      <inertia
        ixx="1.59365628586767E-07"
        ixy="8.54250314742249E-10"
        ixz="-3.40905422018205E-09"
        iyy="7.68751523460339E-07"
        iyz="-2.65062440645536E-09"
        izz="7.26221149125631E-07" />
    </inertial>
    <visual>
      <origin
        xyz="0 0 0"
        rpy="0 0 0" />
      <geometry>
        <mesh
          filename="package://mirte_description/meshes/rear_left_ultrasound_link.STL" />
      </geometry>
      <material
        name="">
        <color
          rgba="0.792156862745098 0.819607843137255 0.933333333333333 1" />
      </material>
    </visual>
    <collision>
      <origin
        xyz="0 0 0"
        rpy="0 0 0" />
      <geometry>
        <mesh
          filename="package://mirte_description/meshes/rear_left_ultrasound_link.STL" />
      </geometry>
    </collision>
  </link>
  <joint
    name="rear_left_ultrasound_joint"
    type="fixed">
    <origin
      xyz="-0.119187021096338 0.0565606470918482 -0.0309999999999999"
      rpy="0 0 1.27409035395586" />
    <parent
      link="base_link" />
    <child
      link="rear_left_ultrasound_link" />
    <axis
      xyz="0 0 0" />
  </joint>
  <link
    name="rear_right_ultrasound_link">
    <inertial>
      <origin
        xyz="4.30733527062716E-05 0.00367564883489802 6.99136578631541E-05"
        rpy="0 0 0" />
      <mass
        value="0.00383513951999245" />
      <inertia
        ixx="1.59365628586768E-07"
        ixy="8.54250314743049E-10"
        ixz="-3.40905422018174E-09"
        iyy="7.68751523460337E-07"
        iyz="-2.65062440645516E-09"
        izz="7.26221149125628E-07" />
    </inertial>
    <visual>
      <origin
        xyz="0 0 0"
        rpy="0 0 0" />
      <geometry>
        <mesh
          filename="package://mirte_description/meshes/rear_right_ultrasound_link.STL" />
      </geometry>
      <material
        name="">
        <color
          rgba="0.792156862745098 0.819607843137255 0.933333333333333 1" />
      </material>
    </visual>
    <collision>
      <origin
        xyz="0 0 0"
        rpy="0 0 0" />
      <geometry>
        <mesh
          filename="package://mirte_description/meshes/rear_right_ultrasound_link.STL" />
      </geometry>
    </collision>
  </link>
  <joint
    name="rear_right_ultrasound_joint"
    type="fixed">
    <origin
      xyz="-0.119187021096338 -0.0565606470918482 -0.031"
      rpy="0 0 1.86750229963393" />
    <parent
      link="base_link" />
    <child
      link="rear_right_ultrasound_link" />
    <axis
      xyz="0 0 0" />
  </joint>
  <link
    name="flag_link">
    <inertial>
      <origin
        xyz="-0.024941 -0.00081775 0.13848"
        rpy="0 0 0" />
      <mass
        value="0" />
      <inertia
        ixx="0.0010881"
        ixy="-2.8836E-06"
        ixz="6.0642E-05"
        iyy="0.001158"
        iyz="1.546E-06"
        izz="7.0587E-05" />
    </inertial>
    <visual>
      <origin
        xyz="0 0 0"
        rpy="0 0 0" />
      <geometry>
        <mesh
          filename="package://mirte_description/meshes/flag_link.STL" />
      </geometry>
      <material
        name="">
        <color
          rgba="0.79608 0.82353 0.93725 1" />
      </material>
    </visual>
    <collision>
      <origin
        xyz="0 0 0"
        rpy="0 0 0" />
      <geometry>
        <mesh
          filename="package://mirte_description/meshes/flag_link.STL" />
      </geometry>
    </collision>
  </link>
  <joint
    name="flag_joint"
    type="fixed">
    <origin
      xyz="-0.12479 -0.0502 0.31705"
      rpy="0 0 0" />
    <parent
      link="base_link" />
    <child
      link="flag_link" />
    <axis
      xyz="0 0 0" />
  </joint>

  <transmission name="front_left_wheel_trans">
      <type>transmission_interface/SimpleTransmission</type>
      <joint name="front_left_wheel_joint">
        <hardwareInterface>hardware_interface/VelocityJointInterface</hardwareInterface>
      </joint>
      <actuator name="front_left_wheel_actuator">
        <mechanicalReduction>1</mechanicalReduction>
      </actuator>
  </transmission>
  
  <transmission name="front_right_wheel_trans">
      <type>transmission_interface/SimpleTransmission</type>
      <joint name="front_right_wheel_joint">
        <hardwareInterface>hardware_interface/VelocityJointInterface</hardwareInterface>
      </joint>
      <actuator name="front_right_wheel_actuator">
        <mechanicalReduction>1</mechanicalReduction>
      </actuator>
  </transmission>

  <transmission name="rear_right_wheel_trans">
      <type>transmission_interface/SimpleTransmission</type>
      <joint name="rear_right_wheel_joint">
        <hardwareInterface>hardware_interface/VelocityJointInterface</hardwareInterface>
      </joint>
      <actuator name="rear_right_wheel_actuator">
        <mechanicalReduction>1</mechanicalReduction>
      </actuator>
    </transmission>

  <transmission name="rear_left_wheel_trans">
      <type>transmission_interface/SimpleTransmission</type>
      <joint name="rear_left_wheel_joint">
        <hardwareInterface>hardware_interface/VelocityJointInterface</hardwareInterface>
      </joint>
      <actuator name="rear_left_wheel_actuator">
        <mechanicalReduction>1</mechanicalReduction>
      </actuator>
    </transmission>

</robot>