<?xml version="1.0"?>
<robot name="mearm">
    
  <link name="base_link">
    <visual>
      <geometry>
	    <box size="0.95 1.425 0.02"/>
      </geometry>
      <material name="yellow">
        <color rgba="1 1 0 0.2"/>
      </material>
      <origin rpy="0 0 0" xyz="0 -0.4 0.0"/>
    </visual>
    <collision>
      <geometry>
	     <box size="0.95 1.425 0.02"/>
      </geometry>
      <origin xyz="0 -0.4 0.0" rpy="0 0 0" />
    </collision>
  </link>

  <link name="torso">
    <visual>
      <geometry>
	    <box size="0.53 0.55 0.45"/>
      </geometry>
      <material name="cyan">
        <color rgba="1 0 1 0.2"/>
      </material>
      <origin rpy="0 0 0" xyz="0 0 0.225"/>
    </visual>
	<collision>
      <geometry>
	    <box size="0.53 0.55 0.45"/>
      </geometry>
      <origin rpy="0 0 0" xyz="0 0 0.225"/>
    </collision>
  </link>

  <link name="lower_arm">
    <visual>
      <geometry>
        <cylinder length="0.8" radius="0.05"/>
      </geometry>
      <material name="yellow"/>
      <origin rpy="0 0 0" xyz="0 0 0.4"/>
    </visual>
	<collision>
      <geometry>
        <cylinder length="0.8" radius="0.05"/>
      </geometry>
      <origin rpy="0 0 0" xyz="0 0 0.4"/>
    </collision>
  </link>

  <link name="upper_arm">
    <visual>
      <geometry>
        <cylinder length="0.8" radius="0.05"/>
      </geometry>
      <material name="yellow"/>
      <origin rpy="0 0 0" xyz="0 0 0.4"/>
    </visual>
	<collision>
      <geometry>
        <cylinder length="0.8" radius="0.05"/>
      </geometry>
      <origin rpy="0 0 0" xyz="0 0 0.4"/>
    </collision>
  </link>

  <link name="hand">
    <visual>
      <geometry>
        <box size="0.05 0.05 0.05"/>
      </geometry>
      <material name="yellow"/>
    </visual>
    <collision>
      <geometry>
        <box size="0.05 0.05 0.05"/>
      </geometry>
      <origin rpy="0 0 0" xyz="0 0 0"/>
    </collision>
  </link>

<!--
  <joint name="fixed" type="fixed">
    <parent link="world"/>
    <child link="base_link"/>
  </joint>
-->

  <joint name="hip" type="revolute">
    <axis xyz="0 0 1"/>
    <parent link="base_link"/>
    <child link="torso"/>
    <origin xyz="0.0 0.0 0.12" rpy="0 0 1.57"/>
    <limit effort="30" velocity="1.0" lower="0.0" upper="3.14" />
  </joint>

  <joint name="shoulder" type="revolute">
    <origin rpy="0 -1.57 0" xyz="0.115 0 0.28"/>
    <parent link="torso"/>
    <child link="lower_arm"/>
    <axis xyz="0 1 0"/>
    <limit effort="30" velocity="1.0" lower="1.15" upper="3.14" />
  </joint>

  <joint name="elbow" type="revolute">
    <origin rpy="0 0 0" xyz="0.0 0.0 0.8"/>
    <parent link="lower_arm"/>
    <child link="upper_arm"/>
    <axis xyz="0 1 0"/>
    <limit effort="30" velocity="1.0" lower="1.54" upper="2.75" />
  </joint>    

  <joint name="wrist" type="revolute">
    <axis xyz="1 0 0"/>
    <parent link="lower_arm"/>
    <child link="hand"/>
    <origin rpy="0 0 0" xyz="0.0 0.0 0.805"/>
    <limit effort="30" velocity="1.0" lower="0.0" upper="2.7" />
  </joint>


</robot>
