<?xml version="1.0" encoding="utf-8"?>
<!-- This URDF was automatically created by SolidWorks to URDF Exporter! Originally created by Stephen Brawner (brawner@gmail.com) 
     Commit Version: 1.6.0-4-g7f85cfe  Build Version: 1.6.7995.38578
     For more information, please see http://wiki.ros.org/sw_urdf_exporter -->
<robot
  name="robot_base" xmlns:xacro="http://www.ros.org/wiki/xacro">
  <xacro:property name="radius" value="0.055" />
  <xacro:property name="length" value="0.05" />
  <xacro:property name="wheel_orientation" value="1 0 0" />
  <xacro:property name="collision_transform" value="0 1.57079632679 1.57079632679" />


  <link
    name="base_link">
    <inertial>
      <origin
        xyz="-0.0111443854086884 -0.000831975562567948 0.00395208351304286"
        rpy="0 0 0" />
      <mass
        value="2.57903452705291" />
      <inertia
        ixx="0.010097194230352"
        ixy="-4.37392111784297E-06"
        ixz="0.000240822381205553"
        iyy="0.0132093250149844"
        iyz="7.47840581370496E-07"
        izz="0.020314109789297" />
    </inertial>
    <visual>
      <origin
        xyz="0 0 0"
        rpy="0 0 0" />
      <geometry>
        <mesh
          filename="package://mirte_description/meshes/base_link.STL" />
      </geometry>
      <material
        name="">
        <color
          rgba="0.529411764705882 0.549019607843137 0.549019607843137 1" />
      </material>
    </visual>
    <collision>
      <origin
        xyz="0 0 0"
        rpy="0 0 0" />
      <geometry>
        <mesh
          filename="package://mirte_description/meshes/base_link.STL" />
      </geometry>
    </collision>
  </link>
  <link
    name="front_left_wheel_link">
    <inertial>
      <origin
        xyz="-1.12107309546694E-10 6.41072041116242E-05 2.92491794673388E-10"
        rpy="0 0 0" />
      <mass
        value="0.266614983225976" />
      <inertia
        ixx="8.05457942774813E-05"
        ixy="-1.2260463258983E-14"
        ixz="1.96734401516725E-15"
        iyy="9.31956038960016E-05"
        iyz="-9.68885005345804E-15"
        izz="8.05457942705124E-05" />
    </inertial>
    <visual>
      <origin
        xyz="0 0 0"
        rpy="0 0 0" />
      <geometry>
        <mesh
          filename="package://mirte_description/meshes/front_left_wheel_link.STL" />
      </geometry>
      <material
        name="">
        <color
          rgba="0.792156862745098 0.819607843137255 0.933333333333333 1" />
      </material>
    </visual>
    <collision>
      <origin
        xyz="0 0 0"
        rpy="${collision_transform}" />
      <geometry>
        <cylinder radius="${radius}" length="${length}" />
        <!-- <mesh filename="package://mirte_description/meshes/front_left_wheel_link.STL" /> -->
      </geometry>
    </collision>
  </link>
  <joint
    name="front_left_wheel_joint"
    type="continuous">
    <origin
      xyz="0.085 0.128 -0.0455"
      rpy="0 0 0" />
    <parent
      link="base_link" />
    <child
      link="front_left_wheel_link" />
    <axis
      xyz="0 -1 0" />
  </joint>
  <link
    name="front_right_wheel_link">
    <inertial>
      <origin
        xyz="-1.90001653299632E-10 6.41072041136781E-05 2.12521250597675E-10"
        rpy="0 0 0" />
      <mass
        value="0.266614983226051" />
      <inertia
        ixx="8.05457942757E-05"
        ixy="-7.6916734798387E-14"
        ixz="-4.58661925987117E-15"
        iyy="9.31956038947894E-05"
        iyz="-9.60110972210022E-15"
        izz="8.05457942710755E-05" />
    </inertial>
    <visual>
      <origin
        xyz="0 0 0"
        rpy="0 0 0" />
      <geometry>
        <mesh
          filename="package://mirte_description/meshes/front_right_wheel_link.STL" />
      </geometry>
      <material
        name="">
        <color
          rgba="0.792156862745098 0.819607843137255 0.933333333333333 1" />
      </material>
    </visual>
    <collision>
      <origin
        xyz="0 0 0"
        rpy="${collision_transform}" />
      <geometry>
        <cylinder radius="${radius}" length="${length}" />
        <!-- <mesh filename="package://mirte_description/meshes/front_right_wheel_link.STL" /> -->
      </geometry>
    </collision>
  </link>
  <joint
    name="front_right_wheel_joint"
    type="continuous">
    <origin
      xyz="0.085 -0.128 -0.0455"
      rpy="0 0 0" />
    <parent
      link="base_link" />
    <child
      link="front_right_wheel_link" />
    <axis
      xyz="0 -1 0" />
  </joint>
  <link
    name="rear_left_wheel_link">
    <inertial>
      <origin
        xyz="-1.90001639421844E-10 6.41072041137336E-05 2.12521319986614E-10"
        rpy="0 0 0" />
      <mass
        value="0.266614983226051" />
      <inertia
        ixx="8.05457942756754E-05"
        ixy="-7.69042802358516E-14"
        ixz="-4.57395491293476E-15"
        iyy="9.31956038947576E-05"
        iyz="-9.59312925333487E-15"
        izz="8.05457942710471E-05" />
    </inertial>
    <visual>
      <origin
        xyz="0 0 0"
        rpy="0 0 0" />
      <geometry>
        <mesh
          filename="package://mirte_description/meshes/rear_left_wheel_link.STL" />
      </geometry>
      <material
        name="">
        <color
          rgba="0.792156862745098 0.819607843137255 0.933333333333333 1" />
      </material>
    </visual>
    <collision>
      <origin
        xyz="0 0 0"
        rpy="${collision_transform}" />
      <geometry>
        <cylinder radius="${radius}" length="${length}" />
        <!-- <mesh filename="package://mirte_description/meshes/rear_left_wheel_link.STL" /> -->
      </geometry>
    </collision>
  </link>
  <joint
    name="rear_left_wheel_joint"
    type="continuous">
    <origin
      xyz="-0.085 0.128 -0.0455"
      rpy="0 0 0" />
    <parent
      link="base_link" />
    <child
      link="rear_left_wheel_link" />
    <axis
      xyz="0 -1 0" />
  </joint>
  <link
    name="rear_right_wheel_link">
    <inertial>
      <origin
        xyz="-1.00091421262327E-10 6.41072041089319E-05 2.94731093697376E-10"
        rpy="0 0 0" />
      <mass
        value="0.26661498322592" />
      <inertia
        ixx="8.05457942778204E-05"
        ixy="-1.2652000339339E-14"
        ixz="4.82096941386991E-17"
        iyy="9.31956038962011E-05"
        iyz="-1.75713136841005E-14"
        izz="8.05457942703287E-05" />
    </inertial>
    <visual>
      <origin
        xyz="0 0 0"
        rpy="0 0 0" />
      <geometry>
        <mesh
          filename="package://mirte_description/meshes/rear_right_wheel_link.STL" />
      </geometry>
      <material
        name="">
        <color
          rgba="0.792156862745098 0.819607843137255 0.933333333333333 1" />
      </material>
    </visual>
    <collision>
      <origin
        xyz="0 0 0"
        rpy="${collision_transform}" />
      <geometry>
        <cylinder radius="${radius}" length="${length}" />
        <!-- <mesh filename="package://mirte_description/meshes/rear_right_wheel_link.STL" /> -->
      </geometry>
    </collision>
  </link>
  <joint
    name="rear_right_wheel_joint"
    type="continuous">
    <origin
      xyz="-0.085 -0.128 -0.0455"
      rpy="0 0 0" />
    <parent
      link="base_link" />
    <child
      link="rear_right_wheel_link" />
    <axis
      xyz="0 -1 0" />
  </joint>
  <link
    name="camera_link">
    <inertial>
      <origin
        xyz="-0.0222605572085065 0.00132191545179521 -0.000392007230496989"
        rpy="0 0 0" />
      <mass
        value="0.188133922243291" />
      <inertia
        ixx="0.000408304025984058"
        ixy="1.91366258287762E-05"
        ixz="-4.27256164755698E-06"
        iyy="6.91459464023262E-05"
        iyz="2.54332903063166E-06"
        izz="0.00044907482518408" />
    </inertial>
    <visual>
      <origin
        xyz="0 0 0"
        rpy="0 0 0" />
      <geometry>
        <mesh
          filename="package://mirte_description/meshes/camera_link.STL" />
      </geometry>
      <material
        name="">
        <color
          rgba="0.250980392156863 0.250980392156863 0.250980392156863 1" />
      </material>
    </visual>
    <collision>
      <origin
        xyz="0 0 0"
        rpy="0 0 0" />
      <geometry>
        <mesh
          filename="package://mirte_description/meshes/camera_link.STL" />
      </geometry>
    </collision>
  </link>
  <joint
    name="camera_joint"
    type="fixed">
    <origin
      xyz="0.14666 0 0.0427"
      rpy="0 0 0" />
    <parent
      link="base_link" />
    <child
      link="camera_link" />
    <axis
      xyz="0 0 0" />
  </joint>
  <link
    name="lidar_link">
    <inertial>
      <origin
        xyz="-3.97749846947626E-10 -9.54386087724289E-05 -0.0118651639742243"
        rpy="0 0 0" />
      <mass
        value="0.100511981883415" />
      <inertia
        ixx="3.39518063996325E-05"
        ixy="-2.92284267117192E-13"
        ixz="1.62111209503273E-12"
        iyy="3.44778101670497E-05"
        iyz="-1.18155796478011E-07"
        izz="4.1935853096105E-05" />
    </inertial>
    <visual>
      <origin
        xyz="0 0 0"
        rpy="0 0 0" />
      <geometry>
        <mesh
          filename="package://mirte_description/meshes/lidar_link.STL" />
      </geometry>
      <material
        name="">
        <color
          rgba="0.501960784313725 0.501960784313725 0.501960784313725 1" />
      </material>
    </visual>
    <collision>
      <origin
        xyz="0 0 0"
        rpy="0 0 0" />
      <geometry>
        <mesh
          filename="package://mirte_description/meshes/lidar_link.STL" />
      </geometry>
    </collision>
  </link>
  <joint
    name="lidar_joint"
    type="fixed">
    <origin
      xyz="0.1005 0 0.0072113"
      rpy="0 0 0" />
    <parent
      link="base_link" />
    <child
      link="lidar_link" />
    <axis
      xyz="0 0 0" />
  </joint>
  <link
    name="front_right_ultrasound_link">
    <inertial>
      <origin
        xyz="4.30733527063271E-05 0.00367564883489799 6.9913657863175E-05"
        rpy="0 0 0" />
      <mass
        value="0.00383513951999245" />
      <inertia
        ixx="1.59365628586767E-07"
        ixy="8.54250314742497E-10"
        ixz="-3.40905422018182E-09"
        iyy="7.6875152346034E-07"
        iyz="-2.65062440645525E-09"
        izz="7.26221149125632E-07" />
    </inertial>
    <visual>
      <origin
        xyz="0 0 0"
        rpy="0 0 0" />
      <geometry>
        <mesh
          filename="package://mirte_description/meshes/front_right_ultrasound_link.STL" />
      </geometry>
      <material
        name="">
        <color
          rgba="0.792156862745098 0.819607843137255 0.933333333333333 1" />
      </material>
    </visual>
    <collision>
      <origin
        xyz="0 0 0"
        rpy="0 0 0" />
      <geometry>
        <mesh
          filename="package://mirte_description/meshes/front_right_ultrasound_link.STL" />
      </geometry>
    </collision>
  </link>
  <joint
    name="front_right_ultrasound_joint"
    type="fixed">
    <origin
      xyz="0.12028 -0.052978 -0.031"
      rpy="0 0 -1.8675" />
    <parent
      link="base_link" />
    <child
      link="front_right_ultrasound_link" />
    <axis
      xyz="0 0 0" />
  </joint>
  <link
    name="front_left_ultrasound_link">
    <inertial>
      <origin
        xyz="-4.30733527062924E-05 -0.00367564883489804 6.99136578631437E-05"
        rpy="0 0 0" />
      <mass
        value="0.00383513951999246" />
      <inertia
        ixx="1.59365628586768E-07"
        ixy="8.54250314742616E-10"
        ixz="3.40905422018196E-09"
        iyy="7.68751523460337E-07"
        iyz="2.65062440645508E-09"
        izz="7.26221149125628E-07" />
    </inertial>
    <visual>
      <origin
        xyz="0 0 0"
        rpy="0 0 0" />
      <geometry>
        <mesh
          filename="package://mirte_description/meshes/front_left_ultrasound_link.STL" />
      </geometry>
      <material
        name="">
        <color
          rgba="0.792156862745098 0.819607843137255 0.933333333333333 1" />
      </material>
    </visual>
    <collision>
      <origin
        xyz="0 0 0"
        rpy="0 0 0" />
      <geometry>
        <mesh
          filename="package://mirte_description/meshes/front_left_ultrasound_link.STL" />
      </geometry>
    </collision>
  </link>
  <joint
    name="front_left_ultrasound_joint"
    type="fixed">
    <origin
      xyz="0.12028 0.052978 -0.031"
      rpy="0 0 1.8675" />
    <parent
      link="base_link" />
    <child
      link="front_left_ultrasound_link" />
    <axis
      xyz="0 0 0" />
  </joint>
  <link
    name="rear_left_ultrasound_link">
    <inertial>
      <origin
        xyz="4.30733527062716E-05 0.00367564883489802 6.99136578631784E-05"
        rpy="0 0 0" />
      <mass
        value="0.00383513951999244" />
      <inertia
        ixx="1.59365628586767E-07"
        ixy="8.54250314742189E-10"
        ixz="-3.40905422018205E-09"
        iyy="7.6875152346034E-07"
        iyz="-2.65062440645534E-09"
        izz="7.26221149125632E-07" />
    </inertial>
    <visual>
      <origin
        xyz="0 0 0"
        rpy="0 0 0" />
      <geometry>
        <mesh
          filename="package://mirte_description/meshes/rear_left_ultrasound_link.STL" />
      </geometry>
      <material
        name="">
        <color
          rgba="0.792156862745098 0.819607843137255 0.933333333333333 1" />
      </material>
    </visual>
    <collision>
      <origin
        xyz="0 0 0"
        rpy="0 0 0" />
      <geometry>
        <mesh
          filename="package://mirte_description/meshes/rear_left_ultrasound_link.STL" />
      </geometry>
    </collision>
  </link>
  <joint
    name="rear_left_ultrasound_joint"
    type="fixed">
    <origin
      xyz="-0.11919 0.056561 -0.031"
      rpy="0 0 1.2741" />
    <parent
      link="base_link" />
    <child
      link="rear_left_ultrasound_link" />
    <axis
      xyz="0 0 0" />
  </joint>
  <link
    name="rear_right_ultrasound_link">
    <inertial>
      <origin
        xyz="4.30733527062716E-05 0.00367564883489802 6.99136578631541E-05"
        rpy="0 0 0" />
      <mass
        value="0.00383513951999245" />
      <inertia
        ixx="1.59365628586768E-07"
        ixy="8.54250314743036E-10"
        ixz="-3.40905422018172E-09"
        iyy="7.68751523460337E-07"
        iyz="-2.65062440645517E-09"
        izz="7.26221149125628E-07" />
    </inertial>
    <visual>
      <origin
        xyz="0 0 0"
        rpy="0 0 0" />
      <geometry>
        <mesh
          filename="package://mirte_description/meshes/rear_right_ultrasound_link.STL" />
      </geometry>
      <material
        name="">
        <color
          rgba="0.792156862745098 0.819607843137255 0.933333333333333 1" />
      </material>
    </visual>
    <collision>
      <origin
        xyz="0 0 0"
        rpy="0 0 0" />
      <geometry>
        <mesh
          filename="package://mirte_description/meshes/rear_right_ultrasound_link.STL" />
      </geometry>
    </collision>
  </link>
  <joint
    name="rear_right_ultrasound_joint"
    type="fixed">
    <origin
      xyz="-0.119187021096338 -0.0565606470918482 -0.031"
      rpy="0 0 1.86750229963393" />
    <parent
      link="base_link" />
    <child
      link="rear_right_ultrasound_link" />
    <axis
      xyz="0 0 0" />
  </joint>

  <transmission name="front_left_wheel_trans">
      <type>transmission_interface/SimpleTransmission</type>
      <joint name="front_left_wheel_joint">
        <hardwareInterface>hardware_interface/VelocityJointInterface</hardwareInterface>
      </joint>
      <actuator name="front_left_wheel_actuator">
        <mechanicalReduction>1</mechanicalReduction>
      </actuator>
  </transmission>
  
  <transmission name="front_right_wheel_trans">
      <type>transmission_interface/SimpleTransmission</type>
      <joint name="front_right_wheel_joint">
        <hardwareInterface>hardware_interface/VelocityJointInterface</hardwareInterface>
      </joint>
      <actuator name="front_right_wheel_actuator">
        <mechanicalReduction>1</mechanicalReduction>
      </actuator>
  </transmission>

  <transmission name="rear_right_wheel_trans">
      <type>transmission_interface/SimpleTransmission</type>
      <joint name="rear_right_wheel_joint">
        <hardwareInterface>hardware_interface/VelocityJointInterface</hardwareInterface>
      </joint>
      <actuator name="rear_right_wheel_actuator">
        <mechanicalReduction>1</mechanicalReduction>
      </actuator>
    </transmission>

  <transmission name="rear_left_wheel_trans">
      <type>transmission_interface/SimpleTransmission</type>
      <joint name="rear_left_wheel_joint">
        <hardwareInterface>hardware_interface/VelocityJointInterface</hardwareInterface>
      </joint>
      <actuator name="rear_left_wheel_actuator">
        <mechanicalReduction>1</mechanicalReduction>
      </actuator>
    </transmission>

</robot>